<robot name="unnamed" version="1.0">
  <joint name="caster_wheel_link_joint" type="fixed">
    <origin rpy="0.00000 0.00000 0.00000" xyz="-0.00134 -0.13045 -0.04759"/>
    <parent link="chassis_link"/>
    <child link="caster_wheel_link"/>
  </joint>
  <joint name="chassis_link_joint" type="fixed">
    <origin rpy="0.00000 0.00000 0.00000" xyz="0.00000 -0.04128 0.00000"/>
    <parent link="base_link"/>
    <child link="chassis_link"/>
  </joint>
  <joint name="left_wheel_joint" type="continuous">
    <origin rpy="-0.00000 1.57080 0.00000" xyz="0.21319 0.09851 -0.00860"/>
    <parent link="chassis_link"/>
    <child link="left_wheel_link"/>
    <axis xyz="0.00000 0.00000 1.00000"/>
  </joint>
  <joint name="laser_joint" type="fixed">
    <origin rpy="-0.00000 -0.00000 -3.14159" xyz="0.00000 0.00000 0.07031"/>
    <parent link="chassis_link"/>
    <child link="lidar_link"/>
  </joint>
  <joint name="right_wheel_joint" type="continuous">
    <origin rpy="3.14159 1.57080 0.00000" xyz="-0.21115 0.09851 -0.00860"/>
    <parent link="chassis_link"/>
    <child link="right_wheel_link"/>
    <axis xyz="0.00000 0.00000 1.00000"/>
  </joint>
  <link name="base_link"/>
  <link name="caster_wheel_link">
    <visual name="caster_wheel">
      <origin rpy="0.00000 0.00000 0.00000" xyz="0.00000 0.00000 0.00000"/>
      <geometry>
        <sphere radius="0.01540"/>
      </geometry>
    </visual>
  </link>
  <link name="chassis_link">
    <visual name="body">
      <origin rpy="0.00000 0.00000 0.00000" xyz="0.00000 0.00000 0.00000"/>
      <geometry>
        <box size="0.40039 0.30040 0.07699"/>
      </geometry>
    </visual>
  </link>
  <link name="left_wheel_link">
    <visual name="left_wheel">
      <origin rpy="0.00000 -0.00000 0.00000" xyz="-0.00000 0.00000 0.00000"/>
      <geometry>
        <cylinder radius="0.05363" length="0.02218"/>
      </geometry>
    </visual>
  </link>
  <link name="lidar_link">
    <visual name="lidar">
      <origin rpy="0.00000 0.00000 0.00000" xyz="-0.00000 -0.00000 0.00000"/>
      <geometry>
        <cylinder radius="0.04914" length="0.05884"/>
      </geometry>
    </visual>
  </link>
  <link name="right_wheel_link">
    <visual name="right_wheel">
      <origin rpy="0.00000 0.00000 -0.00000" xyz="0.00000 0.00000 0.00000"/>
      <geometry>
        <cylinder radius="0.05363" length="0.02004"/>
      </geometry>
    </visual>
  </link>
</robot>